<?xml version="1.0"?>
<sdf version="1.6"
    xmlns:xacro="http://www.ros.org/wiki/xacro">>
    <xacro:property name="heavy_h" value="0.1" />
    <xacro:property name="base_h" value="0.5" />
    <xacro:property name="box_side" value="0.1" />
    <xacro:property name="gbox_l" value="0.25"/>
    <xacro:property name="gbox_w" value="0.1"/>
    <model name="gear_box">
        <link name="heavy_base">
            <!-- position the base such that the bottom touches the floor -->
            <pose>0 0 0.05 0 0 0</pose>
            <inertial>
                <mass>100</mass>                <!-- kg -->
                <inertia>
                    <!-- (mass / 12) * (y*y + z*z) -->
                    <ixx>8.4167</ixx>
                    <ixy>0</ixy>
                    <ixz>0</ixz>
                    <!-- (mass / 12) * (x*x + z*z) -->
                    <iyy>40.417</iyy>
                    <iyz>0</iyz>
                    <!-- (mass / 12) * (y*y + x*x) -->
                    <izz>48.667</izz>
                </inertia>
            </inertial>
            <!-- Same geometry as visual -->
            <collision name="heavy_base_collision">
                <geometry>
                    <box>
                        <size>2.2 1 ${heavy_h}</size>
                    </box>
                </geometry>
            </collision>
            <!-- Same geometry as collision -->
            <visual name="heavy_base_visual">
                <geometry>
                    <box>
                        <size>2.2 1 ${heavy_h}</size>
                    </box>
                </geometry>
                <material>
                    <script>
                        <uri>model://demo_joint_types/materials/scripts</uri>
                        <uri>model://demo_joint_types/materials/textures</uri>
                        <name>demo_joint_types/legend</name>
                    </script>
                </material>
            </visual>
        </link>

        <link name="gearbox_base">
            <!-- Put the bottom of the child on top of the parent
                 z = 0.5 * gearbox_base_sz_z + heavy_base_sz_z
                 x = put it near gearbox label on heavy base
                 -->
            <pose >-.49 0 0.35 0 0 0</pose>
            <inertial>
                <inertia>
                    <!-- (mass / 12) * (y*y + z*z) -->
                    <ixx>0.021667</ixx>
                    <ixy>0</ixy>
                    <ixz>0</ixz>
                    <!-- (mass / 12) * (x*x + z*z) -->
                    <iyy>0.021667</iyy>
                    <iyz>0</iyz>
                    <!-- (mass / 12) * (y*y + x*x) -->
                    <izz>0.0016667</izz>
                </inertia>
            </inertial>
            <!-- Same geometry as visual -->
            <collision name="gearbox_base_collision">
                <geometry>
                    <box>
                        <size>0.1 0.1 0.5</size>
                    </box>
                </geometry>
            </collision>
            <!-- Same geometry as collision -->
            <visual name="gearbox_base_visual">
                <geometry>
                    <box>
                        <size>0.1 0.1 0.5</size>
                    </box>
                </geometry>
                <material>
                    <script>
                        <uri>model://demo_joint_types/materials/scripts</uri>
                        <uri>model://demo_joint_types/materials/textures</uri>
                        <name>demo_joint_types/reference</name>
                    </script>
                </material>
            </visual>
        </link>

        <joint name="gearbox_base_to_heavy_base" type="fixed">
            <parent>heavy_base</parent>
            <child>gearbox_base</child>
        </joint>

        <!-- The reference body for the gearbox -->
        <link name="gearbox_input">
            <!-- Put the arm near the top of the gearbox_base so it swings on it's own
                 z = gearbox_base_sz_z + heavy_base_sz_z - 0.5 * gearbox_input_sz_z
                 y = -0.5 * gearbox_input_sz_y + fudge(0.05)
                 x = gearbox_base_x - 0.5 * gearbox_base_sz_x + 0.5 * gearbox_input_sz_x + fudge(0.01)
                 -->
            <pose >-.38 -0.075 0.55 0 0 0</pose>
            <inertial>
                <inertia>
                    <!-- (mass / 12) * (y*y + z*z) -->
                    <ixx>0.0060417</ixx>
                    <ixy>0</ixy>
                    <ixz>0</ixz>
                    <!-- (mass / 12) * (x*x + z*z) -->
                    <iyy>0.0016667</iyy>
                    <iyz>0</iyz>
                    <!-- (mass / 12) * (y*y + x*x) -->
                    <izz>0.0060417</izz>
                </inertia>
            </inertial>
            <!-- Same geometry as visual -->
            <collision name="gearbox_input_collision">
                <geometry>
                    <box>
                        <size>0.1 0.25 0.1</size>
                    </box>
                </geometry>
            </collision>
            <!-- Same geometry as collision -->
            <visual name="gearbox_input_visual">
                <geometry>
                    <box>
                        <size>0.1 0.25 0.1</size>
                    </box>
                </geometry>
                <material>
                    <script>
                        <uri>model://demo_joint_types/materials/scripts</uri>
                        <uri>model://demo_joint_types/materials/textures</uri>
                        <name>demo_joint_types/parent</name>
                    </script>
                </material>
            </visual>
        </link>
        <!-- The output of the gearbox is a free spinning cylinder -->
        <link name="gearbox_output">
            <gravity>0</gravity>
            <pose >-.3 0.0 0.55 0 1.5708 0</pose>
            <inertial>
                <mass>0.1</mass> <!-- kg -->
                <inertia>
                    <!-- (mass / 12) * (3 * radius * radius + length * length) -->
                    <ixx>0.00027083</ixx>
                    <ixy>0</ixy>
                    <ixz>0</ixz>
                    <!-- (mass / 12) * (3 * radius * radius + length * length) -->
                    <iyy>0.00027083</iyy>
                    <iyz>0</iyz>
                    <!-- mass * radius * radius * 0.5 -->
                    <izz>0.0005</izz>
                </inertia>
            </inertial>
            <!-- Same geometry as visual -->
            <collision name="gearbox_output_collision">
                <geometry>
                    <cylinder>
                        <radius>0.1</radius>
                        <length>0.05</length>
                    </cylinder>
                </geometry>
            </collision>
            <!-- Same geometry as collision -->
            <visual name="gearbox_output_visual">
                <geometry>
                    <cylinder>
                        <radius>0.1</radius>
                        <length>0.05</length>
                    </cylinder>
                </geometry>
                <material>
                    <script>
                        <uri>model://demo_joint_types/materials/scripts</uri>
                        <uri>model://demo_joint_types/materials/textures</uri>
                        <name>demo_joint_types/child</name>
                    </script>
                </material>
            </visual>
        </link>

        <!-- Gearbox links revolute joints, so create a couple revolute joints -->
        <joint name="gearbox_input_joint" type="revolute">
            <parent>gearbox_base</parent>
            <child>gearbox_input</child>
            <axis>
                <xyz>1 0 0</xyz>
            </axis>
            <pose>0 0.075 0 0 0 0</pose>
        </joint>
        <joint name="gearbox_output_joint" type="revolute">
            <parent>gearbox_base</parent>
            <child>gearbox_output</child>
            <axis>
                <xyz>0 0 1</xyz>
            </axis>
            <pose>0 0 0 0 0 0</pose>
        </joint>
        <joint name="gearbox_demo" type="gearbox">
            <parent>gearbox_input</parent>
            <child>gearbox_output</child>
            <gearbox_reference_body>gearbox_base</gearbox_reference_body>
            <gearbox_ratio>5</gearbox_ratio>
            <!-- input axis (relative to child) -->
            <axis>
                <xyz>0 0 1</xyz>
            </axis>
            <!-- output axis (relative to child) -->
            <axis2>
                <xyz>0 0 1</xyz>
            </axis2>
        </joint>
    </model>
</sdf>