<?xml version="1.0" ?>
<!-- =================================================================================== -->
<!-- |    This document was autogenerated by xacro from /home/user/projects/wasp/gz/models/prismatic_demo/model.sdf.xacro | -->
<!-- |    EDITING THIS FILE BY HAND IS NOT RECOMMENDED                                 | -->
<!-- =================================================================================== -->
<sdf version="1.5">
  <model name="prismatic_joint">
    <link name="heavy_base">
      <!-- position the base such that the bottom touches the floor -->
      <pose>0 0 0.05 0 0 0</pose>
      <inertial>
        <mass>100</mass>
        <!-- kg -->
        <inertia>
          <!-- (mass / 12) * (y*y + z*z) -->
          <ixx>8.4167</ixx>
          <ixy>0</ixy>
          <ixz>0</ixz>
          <!-- (mass / 12) * (x*x + z*z) -->
          <iyy>40.417</iyy>
          <iyz>0</iyz>
          <!-- (mass / 12) * (y*y + x*x) -->
          <izz>48.667</izz>
        </inertia>
      </inertial>
      <!-- Same geometry as visual -->
      <collision name="heavy_base_collision">
        <geometry>
          <box>
            <size>2.2 1 0.1</size>
          </box>
        </geometry>
      </collision>
      <!-- Same geometry as collision -->
      <visual name="heavy_base_visual">
        <geometry>
          <box>
            <size>2.2 1 0.1</size>
          </box>
        </geometry>
        <material>
          <script>
            <uri>model://demo_joint_types/materials/scripts</uri>
            <uri>model://demo_joint_types/materials/textures</uri>
            <name>demo_joint_types/legend</name>
          </script>
        </material>
      </visual>
    </link>
    <link name="prismatic_base">
      <!-- Put the bottom of base on top of the heavy base -->
      <pose>0 0 0.35 0 0 0</pose>
      <inertial>
        <inertia>
          <!-- (mass / 12) * (y*y + z*z) -->
          <ixx>0.021667</ixx>
          <ixy>0</ixy>
          <ixz>0</ixz>
          <!-- (mass / 12) * (x*x + z*z) -->
          <iyy>0.021667</iyy>
          <iyz>0</iyz>
          <!-- (mass / 12) * (y*y + x*x) -->
          <izz>0.0016667</izz>
        </inertia>
      </inertial>
      <!-- Same geometry as visual -->
      <collision name="prismatic_base_collision">
        <geometry>
          <box>
            <size>0.1 0.1 0.5</size>
          </box>
        </geometry>
      </collision>
      <!-- Same geometry as collision -->
      <visual name="prismatic_base_visual">
        <geometry>
          <box>
            <size>0.1 0.1 0.5</size>
          </box>
        </geometry>
        <material>
          <script>
            <uri>model://demo_joint_types/materials/scripts</uri>
            <uri>model://demo_joint_types/materials/textures</uri>
            <name>demo_joint_types/parent</name>
          </script>
        </material>
      </visual>
    </link>
    <joint name="prismatic_base_to_heavy_base" type="fixed">
      <parent>heavy_base</parent>
      <child>prismatic_base</child>
    </joint>
    <link name="prismatic_slide">
      <!-- Put the slide near the top of the base -->
      <pose>0.2 0 0.55 0 0 0</pose>
      <inertial>
        <inertia>
          <!-- (mass / 12) * (y*y + z*z) -->
          <ixx>0.0060417</ixx>
          <ixy>0</ixy>
          <ixz>0</ixz>
          <!-- (mass / 12) * (x*x + z*z) -->
          <iyy>0.0060417</iyy>
          <iyz>0</iyz>
          <!-- (mass / 12) * (y*y + x*x) -->
          <izz>0.0016667</izz>
        </inertia>
      </inertial>
      <!-- Same geometry as visual -->
      <collision name="prismatic_slide_collision">
        <geometry>
          <box>
            <size>0.1 0.1 0.25</size>
          </box>
        </geometry>
      </collision>
      <!-- Same geometry as collision -->
      <visual name="prismatic_slide_visual">
        <geometry>
          <box>
            <size>0.1 0.1 0.25</size>
          </box>
        </geometry>
        <material>
          <script>
            <uri>model://demo_joint_types/materials/scripts</uri>
            <uri>model://demo_joint_types/materials/textures</uri>
            <name>demo_joint_types/child</name>
          </script>
        </material>
      </visual>
    </link>
    <joint name="prismatic_demo" type="prismatic">
      <parent>prismatic_base</parent>
      <child>prismatic_slide</child>
      <axis>
        <xyz>0 1 0</xyz>
        <!-- Make it springy to keep the demo moving -->
        <limit>
          <lower>-0.25</lower>
          <upper>0.25</upper>
        </limit>
        <dynamics>
          <spring_stiffness>100</spring_stiffness>
        </dynamics>
      </axis>
    </joint>
  </model>
</sdf>
